<?xml version="1.0" ?>
<robot name="Robot_Gantry_Gazebo" xmlns:xacro="http://www.ros.org/wiki/xacro">

<xacro:include filename="$(find robot_gantry_description)/urdf/materials.xacro" />
<xacro:include filename="$(find robot_gantry_description)/urdf/Robot_Gantry_Gazebo.trans" />
<xacro:include filename="$(find robot_gantry_description)/urdf/Robot_Gantry_Gazebo.gazebo" />
<link name="world" />
<link name="base_link">
  <inertial>
    <origin xyz="0.22891719764184684 0.00041376831351214394 0.23185797143719683" rpy="0 0 0"/>
    <mass value="12.057599999999999"/>
    <inertia ixx="0.233114" iyy="0.816701" izz="0.586803" ixy="0.0" iyz="0.0" ixz="0.0"/>
  </inertial>
  <visual>
    <origin xyz="0 0 0" rpy="0 0 0"/>
    <geometry>
      <mesh filename="file:///home/george/meshes/base_link.stl" scale="0.001 0.001 0.001"/>
    </geometry>
    <material name="silver"/>
  </visual>
  <collision>
    <origin xyz="0 0 0" rpy="0 0 0"/>
    <geometry>
      <mesh filename="file:///home/george/meshes/base_link.stl" scale="0.001 0.001 0.001"/>
    </geometry>
  </collision>
</link>

<link name="z_axis_1">
  <inertial>
    <origin xyz="1.9764184683301877e-07 -2.3168648784210877e-07 0.019999971437196784" rpy="0 0 0"/>
    <mass value="1.8840000000000001"/>
    <inertia ixx="0.002512" iyy="0.000644" izz="0.002653" ixy="-0.0" iyz="-0.0" ixz="-0.0"/>
  </inertial>
  <visual>
    <origin xyz="-0.228917 -0.040414 -0.251858" rpy="0 0 0"/>
    <geometry>
      <mesh filename="file:///home/george/meshes/z_axis_1.stl" scale="0.001 0.001 0.001"/>
    </geometry>
    <material name="silver"/>
  </visual>
  <collision>
    <origin xyz="-0.228917 -0.040414 -0.251858" rpy="0 0 0"/>
    <geometry>
      <mesh filename="file:///home/george/meshes/z_axis_1.stl" scale="0.001 0.001 0.001"/>
    </geometry>
  </collision>
</link>

<link name="y_axis_1">
  <inertial>
    <origin xyz="0.24000019764184685 0.019999768313512148 -2.8562803150444793e-08" rpy="0 0 0"/>
    <mass value="6.0287999999999995"/>
    <inertia ixx="0.001608" iyy="0.116557" izz="0.116557" ixy="-0.0" iyz="0.0" ixz="0.0"/>
  </inertial>
  <visual>
    <origin xyz="0.011083 -0.020414 -0.231858" rpy="0 0 0"/>
    <geometry>
      <mesh filename="file:///home/george/meshes/y_axis_1.stl" scale="0.001 0.001 0.001"/>
    </geometry>
    <material name="silver"/>
  </visual>
  <collision>
    <origin xyz="0.011083 -0.020414 -0.231858" rpy="0 0 0"/>
    <geometry>
      <mesh filename="file:///home/george/meshes/y_axis_1.stl" scale="0.001 0.001 0.001"/>
    </geometry>
  </collision>
</link>

<link name="End_effector_1">
  <inertial>
    <origin xyz="-0.19891823531161548 0.01352440186466668 -0.20086693056215876" rpy="0 0 0"/>
    <mass value="1.3353102876458012"/>
    <inertia ixx="0.001636" iyy="0.001388" izz="0.001431" ixy="0.0" iyz="0.000103" ixz="-0.0"/>
  </inertial>
  <visual>
    <origin xyz="-0.427834 0.039172 -0.503716" rpy="0 0 0"/>
    <geometry>
      <mesh filename="file:///home/george/meshes/End_effector_1.stl" scale="0.001 0.001 0.001"/>
    </geometry>
    <material name="silver"/>
  </visual>
  <collision>
    <origin xyz="-0.427834 0.039172 -0.503716" rpy="0 0 0"/>
    <geometry>
      <mesh filename="file:///home/george/meshes/End_effector_1.stl" scale="0.001 0.001 0.001"/>
    </geometry>
  </collision>
</link>

<link name="stand_1">
  <inertial>
    <origin xyz="0.24000019764184735 -0.02471955391898048 0.23667997143721392" rpy="0 0 0"/>
    <mass value="9.201122274860012"/>
    <inertia ixx="0.31766" iyy="0.629215" izz="0.317662" ixy="-0.0" iyz="0.0" ixz="-0.0"/>
  </inertial>
  <visual>
    <origin xyz="0.011083 0.019586 0.008142" rpy="0 0 0"/>
    <geometry>
      <mesh filename="file:///home/george/meshes/stand_1.stl" scale="0.001 0.001 0.001"/>
    </geometry>
    <material name="silver"/>
  </visual>
  <collision>
    <origin xyz="0.011083 0.019586 0.008142" rpy="0 0 0"/>
    <geometry>
      <mesh filename="file:///home/george/meshes/stand_1.stl" scale="0.001 0.001 0.001"/>
    </geometry>
  </collision>
</link>


<!-- Add a joint to align the base_link with the world frame -->
<joint name="world_base_joint" type="fixed">
  <parent link="world"/>
  <child link="base_link"/>
  <origin xyz="0 1 0.15" rpy="1.57 0 0"/>
</joint>

<joint name="Slider 3" type="prismatic">
  <origin xyz="0.24 0.02 0.02" rpy="0 0 0"/>
  <parent link="y_axis_1"/>
  <child link="z_axis_1"/>
  <axis xyz="1.0 0.0 -0.0"/>
  <limit upper="0.175" lower="-0.175" effort="100" velocity="100"/>
</joint>

<joint name="Slider 4" type="prismatic">
  <origin xyz="-0.011083 0.020414 0.231858" rpy="0 0 0"/>
  <parent link="base_link"/>
  <child link="y_axis_1"/>
  <axis xyz="0.0 0.0 1.0"/>
  <limit upper="0.18" lower="-0.18" effort="100" velocity="100"/>
</joint>

<joint name="Slider 7" type="prismatic">
  <origin xyz="0.198917 -0.079586 0.251858" rpy="0 0 0"/>
  <parent link="z_axis_1"/>
  <child link="End_effector_1"/>
  <axis xyz="-0.0 1.0 0.0"/>
  <limit upper="-0.003" lower="-0.05" effort="100" velocity="100"/>
</joint>

<joint name="Rigid 9" type="fixed">
  <origin xyz="-0.011083 -0.019586 -0.008142" rpy="0 0 0"/>
  <parent link="base_link"/>
  <child link="stand_1"/>
</joint>

</robot>
